ROOT: tox-gh-actions won't override envlist because tox is not running in GitHub Actions
py$(PYV): remove tox env folder $(@D)/.tox/py$(PYV)
py$(PYV): commands[0]> python -m pytest
============================= test session starts ==============================
platform sunos5 -- Python $(PYTHON_VERSION).X -- $(@D)/.tox/py$(PYV)/bin/python
cachedir: .tox/py$(PYV)/.pytest_cache
rootdir: $(@D)
configfile: pytest.ini
collecting ... collected 45 items

::project PASSED
conftest.py::black PASSED
conftest.py::mypy PASSED
conftest.py::mypy-status PASSED
docs/conf.py::black PASSED
docs/conf.py::mypy PASSED
jaraco/functools/__init__.py::black PASSED
jaraco/functools/__init__.py::jaraco.functools.__init__.apply PASSED
jaraco/functools/__init__.py::jaraco.functools.__init__.assign_params PASSED
jaraco/functools/__init__.py::jaraco.functools.__init__.bypass_unless PASSED
jaraco/functools/__init__.py::jaraco.functools.__init__.bypass_when PASSED
jaraco/functools/__init__.py::jaraco.functools.__init__.compose PASSED
jaraco/functools/__init__.py::jaraco.functools.__init__.except_ PASSED
jaraco/functools/__init__.py::jaraco.functools.__init__.identity PASSED
jaraco/functools/__init__.py::jaraco.functools.__init__.invoke PASSED
jaraco/functools/__init__.py::jaraco.functools.__init__.method_cache PASSED
jaraco/functools/__init__.py::jaraco.functools.__init__.once PASSED
jaraco/functools/__init__.py::jaraco.functools.__init__.pass_none PASSED
jaraco/functools/__init__.py::jaraco.functools.__init__.print_yielded PASSED
jaraco/functools/__init__.py::jaraco.functools.__init__.result_invoke PASSED
jaraco/functools/__init__.py::jaraco.functools.__init__.retry PASSED
jaraco/functools/__init__.py::jaraco.functools.__init__.save_method_args PASSED
jaraco/functools/__init__.pyi::mypy PASSED                               [100%]Clearing the cache
test_functools.py::TestMethodCache::test_deepcopy PASSED
test_functools.py::TestMethodCache::test_non_data_property XFAIL (ca...)
test_functools.py::TestMethodCache::test_property XFAIL (can't repla...)
test_functools.py::TestMethodCache::test_special_methods PASSED
test_functools.py::TestRetry::test_cleanup_called_on_exception PASSED
test_functools.py::TestRetry::test_decorator PASSED
test_functools.py::TestRetry::test_decorator_with_arg PASSED
test_functools.py::TestRetry::test_default_does_not_retry PASSED
test_functools.py::TestRetry::test_default_traps_nothing PASSED
test_functools.py::TestRetry::test_infinite_retries PASSED
test_functools.py::TestRetry::test_retry_call_fails PASSED
test_functools.py::TestRetry::test_retry_call_succeeds PASSED
test_functools.py::TestRetry::test_retry_exception_superclass PASSED
test_functools.py::TestRetry::test_retry_multiple_exceptions PASSED
test_functools.py::TestRetry::test_set_to_fail PASSED
test_functools.py::TestRetry::test_with_arg PASSED
test_functools.py::TestThrottler::test_function_throttled PASSED
test_functools.py::TestThrottler::test_reconstruct_unwraps PASSED
test_functools.py::TestThrottler::test_throttled_method PASSED
test_functools.py::black PASSED
test_functools.py::mypy PASSED


===================================== mypy =====================================

Success: no issues found in 4 source files
======== 42 passed, 2 xfailed ========
  py$(PYV): OK
  congratulations :)
